Workbook

Sheet Combined Manoa Data
B2: Date | C2: Site ID | D2: δ18O | E2: δ2H | F2: d-excess (‰) | G2: Temperature | H2: Discharge (m3/s) | I2: Rain or Stream | J2: Elevation (ft) | K2: Precipitation (mm) | L2: Qgw/Qr% | M2: Evaporation Rate (mm/hr) | N2: Rain δ18O | O2: Rain δ2H | P2: Groundwater δ18O | Q2: Groundwater δ2H | R2: 3H
B3: 44970.399 | C3: 1 | D3: -2.6 | E3: -6.7 | F3: =E3 - (8*D3) -> 14.1 | G3: 18 | H3: =0.0283168466*'Hailey''s Data'!I1 -> 0.43891112 | I3: Stream | J3: 460 | K3: 11.9 | L3: 13.090518 | M3: 0.0771006 | N3: -2.5 | O3: -7 | P3: -2.42 | Q3: -4.63
B4: 44970.429 | C4: 2 | D4: -1.9 | E4: -2.2 | F4: =E4 - (8*D4) -> 13 | G4: 18.8 | H4: =0.0283168466*'Hailey''s Data'!I2 -> 0.3511289 | I4: Stream | J4: 270 | K4: 11.9 | L4: 6.5743177 | M4: 0.1256385 | N4: -2.5 | O4: -7 | P4: -2.42 | Q4: -4.63
B5: 44972.373 | C5: 6 | D5: -4 | E5: -21.4 | F5: =E5 - (8*D5) -> 10.6 | G5: 18.5 | H5: =0.0283168466*'Hailey''s Data'!I3 -> 0.43891112 | I5: Stream | J5: 5 | K5: 20.8 | L5: 6.7502481 | M5: 0.00559101 | N5: -6 | O5: -37.1 | P5: -2.42 | Q5: -4.63
B6: 44972.398 | C6: 6 | D6: -3.9 | E6: -20.6 | F6: =E6 - (8*D6) -> 10.6 | G6: 18.5 | H6: =0.0283168466*'Hailey''s Data'!I4 -> 0.41059428 | I6: Stream | J6: 5 | K6: 20.8 | L6: 16.638544 | M6: 0.00559101 | N6: -6 | O6: -37.1 | P6: -2.42 | Q6: -4.63
B7: 44974.371 | C7: 7 | D7: -8.3 | E7: -57.5 | F7: =E7 - (8*D7) -> 8.9 | G7: 19.4 | H7: =0.0283168466*'Hailey''s Data'!I5 -> 0.62580231 | I7: Stream | J7: 5 | K7: 28.2 | L7: 27.129651 | M7: 0.00523663 | N7: -6 | O7: -37.1 | P7: -2.42 | Q7: -4.63
B8: 44974.385 | C8: 7 | D8: -8.4 | E8: -58.3 | F8: =E8 - (8*D8) -> 8.9 | G8: 19.6 | H8: =0.0283168466*'Hailey''s Data'!I6 -> 0.54368345 | I8: Stream | J8: 5 | K8: 28.2 | L8: 1.9843223 | M8: 0.00523663 | N8: -6 | O8: -37.1 | P8: -2.42 | Q8: -4.63
B9: 44974.433 | C9: 3 | D9: -5 | E9: -26.9 | F9: =E9 - (8*D9) -> 13.1 | G9: 18.4 | H9: =0.0283168466*'Hailey''s Data'!I7 -> 0.50403987 | I9: Stream | J9: 230 | K9: 28.2 | L9: 0.29788659 | M9: 0.0106991 | N9: -6 | O9: -37.1 | P9: -2.42 | Q9: -4.63
B10: 44977.372 | C10: 1 | D10: -3.7 | E10: -14.1 | F10: =E10 - (8*D10) -> 15.5 | G10: 17.7 | H10: =0.0283168466*'Hailey''s Data'!I8 -> 0.48421808 | I10: Stream | J10: 460 | K10: 30.5 | L10: 0.43056379 | M10: 0.240284 | N10: -6 | O10: -37.1 | P10: -2.42 | Q10: -4.63
B11: 44977.393 | C11: 1 | D11: -2.6 | E11: -7.6 | F11: =E11 - (8*D11) -> 13.2 | G11: 18.7 | H11: =0.0283168466*'Hailey''s Data'!I9 -> 0.42758438 | I11: Stream | J11: 460 | K11: 30.5 | L11: 1.7414699 | M11: 0.240284 | N11: -6 | O11: -37.1 | P11: -2.42 | Q11: -4.63
B12: 44977.435 | C12: 3 | D12: -3.1 | E12: -10.6 | F12: =E12 - (8*D12) -> 14.2 | G12: 19.3 | H12: =0.0283168466*'Hailey''s Data'!I10 -> 0.43324775 | I12: Stream | J12: 230 | K12: 30.5 | L12: 1.741099 | M12: 0.0306191 | N12: -6 | O12: -37.1 | P12: -2.42 | Q12: -4.63
B13: 44977.449 | C13: 2 | D13: -3.1 | E13: -10.3 | F13: =E13 - (8*D13) -> 14.5 | G13: 18.9 | H13: =0.0283168466*'Hailey''s Data'!I11 -> 0.39926754 | I13: Stream | J13: 270 | K13: 30.5 | L13: 0.27207777 | M13: 0.0771006 | N13: -6 | O13: -37.1 | P13: -2.42 | Q13: -4.63
B14: 44979.367 | C14: 4 | D14: -2.5 | E14: -6.5 | F14: =E14 - (8*D14) -> 13.5 | G14: 19.3 | H14: =0.0283168466*'Hailey''s Data'!I12 -> 0.41908933 | I14: Stream | J14: 80 | K14: 31.8 | L14: 18.101799 | M14: 0.0948266 | N14: -3.1 | O14: -13.6 | P14: -2.42 | Q14: -4.63
... B95: 45266.468 | C95: 4 | D95: -2.4 | E95: -5.1 | F95: =E95 - (8*D95) -> 14.1 | G95: 22.5 | H95: =0.0283168466*'Hailey''s Data'!I93 -> 0.058615872 | I95: Stream | J95: 80 | K95: 24.1 | L95: 6.6731263 | M95: 0.210845 | N95: -4.6 | O95: -25.2 | P95: -2.42 | Q95: -4.63
B96: 45344.601 | C96: 1 | D96: -2.4 | E96: -2.5 | F96: =E96 - (8*D96) -> 16.7 | G96: 19.5 | H96: =0.0283168466*'Hailey''s Data'!I94 -> 4.1342596 | I96: Stream | J96: 460 | K96: 7.1 | L96: 2.5600691 | M96: 0.397368 | P96: -2.42 | Q96: -4.63
B97: 45344.64 | C97: 2 | D97: -2.2 | E97: -3.7 | F97: =E97 - (8*D97) -> 13.9 | G97: 22.8 | H97: =0.0283168466*'Hailey''s Data'!I95 -> 3.5396058 | I97: Stream | J97: 270 | K97: 7.1 | L97: 5.9383414 | M97: 0.159402 | P97: -2.42 | Q97: -4.63
B98: 45344.664 | C98: 3 | D98: -2.6 | E98: -5.6 | F98: =E98 - (8*D98) -> 15.2 | G98: 22.5 | H98: =0.0283168466*'Hailey''s Data'!I96 -> 0.33980216 | I98: Stream | J98: 230 | K98: 7.1 | L98: 7.1595382 | M98: 0.0581616 | P98: -2.42 | Q98: -4.63
B99: 45344.681 | C99: 4 | D99: -2.4 | E99: -4.8 | F99: =E99 - (8*D99) -> 14.4 | G99: 23.6 | H99: =0.0283168466*'Hailey''s Data'!I97 -> 0.33980216 | I99: Stream | J99: 80 | K99: 7.1 | L99: 9.4278579 | M99: 0.168701 | P99: -2.42 | Q99: -4.63
B100: 45345.381 | C100: 6 | D100: -1.6 | E100: 1.3 | F100: =E100 - (8*D100) -> 14.1 | G100: 21 | H100: =0.0283168466*'Hailey''s Data'!I98 -> 0.33980216 | I100: Stream | J100: 80 | K100: 10.9 | L100: 4.7944548 | M100: 0.00559101 | P100: -2.42 | Q100: -4.63
B101: 45345.411 | C101: 6 | D101: -1.5 | E101: 2.1 | F101: =E101 - (8*D101) -> 14.1 | G101: 21.2 | H101: =0.0283168466*'Hailey''s Data'!I99 -> 0.33130711 | I101: Stream | J101: 80 | K101: 10.9 | L101: 8.2670822 | M101: 0.00559101 | P101: -2.42 | Q101: -4.63
B102: 45351.558 | C102: 7 | D102: -2.4 | E102: -3.2 | F102: =E102 - (8*D102) -> 16 | G102: 24.4 | H102: =0.0283168466*'Hailey''s Data'!I100 -> 0.54651514 | I102: Stream | J102: 5 | K102: 53.8 | L102: 0.93092234 | M102: 0.0223054 | P102: -2.42 | Q102: -4.63
B103: 45351.58 | C103: 7 | D103: -2.3 | E103: -2.5 | F103: =E103 - (8*D103) -> 15.9 | G103: 23.8 | H103: =0.0283168466*'Hailey''s Data'!I101 -> 0.68809937 | I103: Stream | J103: 5 | K103: 53.8 | L103: 2.7158395 | M103: 0.0223054 | P103: -2.42 | Q103: -4.63
B104: 45351.612 | C104: 5 | D104: -2.4 | E104: -3.1 | F104: =E104 - (8*D104) -> 16.1 | G104: 23.8 | H104: =0.0283168466*'Hailey''s Data'!I102 -> 0.23333082 | I104: Stream | J104: 80 | K104: 53.8 | L104: 6.2799907 | M104: 0.0669704 | P104: -2.42 | Q104: -4.63
B105: 46001.361 | C105: 5 | D105: -2.3 | E105: -3.8 | F105: =E105 - (8*D105) -> 14.6 | G105: 21.6 | H105: 0.096818425 | I105: Stream | J105: 80 | K105: 0 | L105: 13.077484 | M105: 0.0111231 | P105: -2.42 | Q105: -4.63 | R105: 0.49
B106: 46001.41 | C106: 4 | D106: -2.4 | E106: -4.1 | F106: =E106 - (8*D106) -> 15.1 | G106: 21.4 | H106: 0.07387085 | I106: Stream | J106: 80 | K106: 0 | L106: 32.712149 | M106: 0.0909407 | P106: -2.42 | Q106: -4.63 | R106: 0.52
B107: 46001.474 | C107: 1 | D107: -2.1 | E107: -3.3 | F107: =E107 - (8*D107) -> 13.5 | G107: 22 | H107: 0.0031959 | I107: Stream | J107: 460 | K107: 0 | L107: 10.2811 | M107: 0.305407 | P107: -2.42 | Q107: -4.63 | R107: 0.5
B108: 46001.51 | C108: 2 | D108: -2.1 | E108: -2.7 | F108: =E108 - (8*D108) -> 14.1 | G108: 21.9 | H108: 0.01506689 | I108: Stream | J108: 270 | K108: 0 | L108: 7.0312998 | M108: 0.162014 | P108: -2.42 | Q108: -4.63 | R108: 0.47
B109: 46001.536 | C109: 3 | D109: -2.4 | E109: -4.1 | F109: =E109 - (8*D109) -> 15.1 | G109: 24 | H109: 0.07387085 | I109: Stream | J109: 230 | K109: 0 | L109: 10.034531 | M109: 0.0603415 | P109: -2.42 | Q109: -4.63 | R109: 0.53
B110: 46001.601 | C110: 6 | D110: -2.1 | E110: -3.3 | F110: =E110 - (8*D110) -> 13.5 | G110: 24.7 | H110: 0.1012935 | I110: Stream | J110: 80 | K110: 0 | L110: 8.0372761 | M110: 0.0215673 | P110: -2.42 | Q110: -4.63 | R110: 0.4
B111: 46002 | C111: 1 | D111: -1.4 | E111: 4 | F111: =E111 - (8*D111) -> 15.2 | G111: 20 | H111: =0.02832*1.76 -> 0.0498432 | I111: Rain | J111: 460 | K111: 11.684 | N111: -1.4 | O111: 4 | P111: -2.42 | Q111: -4.63
B112: 46002 | C112: 1 | D112: -1.4 | E112: 4.2 | F112: =E112 - (8*D112) -> 15.4 | G112: 20 | H112: =0.02832*1.76 -> 0.0498432 | I112: Rain | J112: 460 | K112: 11.684 | N112: -1.4 | O112: 4.2 | P112: -2.42 | Q112: -4.63
B113: 46002.396 | C113: 5 | D113: -2.3 | E113: -3.6 | F113: =E113 - (8*D113) -> 14.8 | G113: 22.1 | H113: 0.1089295 | I113: Stream | J113: 80 | K113: 0 | L113: 1.2716559 | M113: 0.0327912 | P113: -2.42 | Q113: -4.63 | R113: 0.49
B114: 46022 | C114: 1 | D114: -2.2 | E114: -4.3 | F114: =E114 - (8*D114) -> 13.3 | G114: 22 | H114: =0.02832*6.01 -> 0.1702032 | I114: Rain | J114: 460 | K114: 363.474 | N114: -2.2 | O114: -4.3 | P114: -2.42 | Q114: -4.63
B115: 46052 | C115: 1 | D115: -2.4 | E115: -3.9 | F115: =E115 - (8*D115) -> 15.3 | G115: 21 | H115: =0.02832*6.64 -> 0.1880448 | I115: Rain | J115: 460 | K115: 263.906 | N115: -2.4 | O115: -3.9 | P115: -2.42 | Q115: -4.63
B116: 46056 | C116: 1 | D116: -1.6 | E116: 0.3 | F116: =E116 - (8*D116) -> 13.1 | G116: 24 | H116: =0.02832*2.31 -> 0.0654192 | I116: Rain | J116: 460 | K116: 10.16 | N116: -1.6 | O116: 0.3 | P116: -2.42 | Q116: -4.63
B117: 46063.515 | C117: 2 | D117: -2.4 | E117: -3.5 | F117: =E117 - (8*D117) -> 15.7 | G117: 20.7 | H117: 0.44147608 | I117: Stream | J117: 270 | K117: 25.4 | L117: 2.6882586 | M117: 0.172401 | N117: -2.8 | O117: -7.5 | P117: -2.42 | Q117: -4.63 | R117: 0.61
B118: 46063.522 | C118: 3 | D118: -2.4 | E118: -3.6 | F118: =E118 - (8*D118) -> 15.6 | G118: 21 | H118: 2.1644953 | I118: Stream | J118: 230 | K118: 25.4 | L118: 4.90549 | M118: 0.0636733 | N118: -2.8 | O118: -7.5 | P118: -2.42 | Q118: -4.63 | R118: 0.66
B119: 46063.531 | C119: 4 | D119: -2.2 | E119: -2.8 | F119: =E119 - (8*D119) -> 14.8 | G119: 22.1 | H119: 2.1644953 | I119: Stream | J119: 80 | K119: 25.4 | L119: 5.3351095 | M119: 0.2293 | N119: -2.8 | O119: -7.5 | P119: -2.42 | Q119: -4.63 | R119: 0.44
B120: 46063.539 | C120: 5 | D120: -2.2 | E120: -2.7 | F120: =E120 - (8*D120) -> 14.9 | G120: 22.4 | H120: 2.836884 | I120: Stream | J120: 80 | K120: 25.4 | L120: 4.2030932 | M120: 0.0677443 | N120: -2.8 | O120: -7.5 | P120: -2.42 | Q120: -4.63 | R120: 0.66
B121: 46063.563 | C121: 6 | D121: -2.1 | E121: -2.7 | F121: =E121 - (8*D121) -> 14.1 | G121: 22.3 | H121: 3.1917515 | I121: Stream | J121: 80 | K121: 25.4 | L121: 2.0216429 | M121: 0.0233487 | N121: -2.8 | O121: -7.5 | P121: -2.42 | Q121: -4.63 | R121: 0.57
...

Sheet Sheet3
B2: Date | C2: Site ID | D2: δ18O | E2: δ2H | F2: d-excess (‰) | G2: Temperature | H2: Discharge (m3/s) | I2: Rain or Stream | J2: Elevation (ft) | K2: Precipitation (mm) | L2: Qgw/Qr% | M2: Evaporation Rate (mm/hr) | N2: Rain δ18O | O2: Rain δ2H | P2: Groundwater δ18O | Q2: Groundwater δ2H | R2: 3H
B3: 46001.361 | C3: 5 | D3: -2.3 | E3: -3.8 | F3: =E3 - (8*D3) -> 14.6 | G3: 21.6 | H3: 0.096818425 | I3: Stream | J3: 80 | K3: 0 | L3: 13.077484 | M3: 0.0111231 | P3: -2.42 | Q3: -4.63 | R3: 0.49
B4: 46001.41 | C4: 4 | D4: -2.4 | E4: -4.1 | F4: =E4 - (8*D4) -> 15.1 | G4: 21.4 | H4: 0.07387085 | I4: Stream | J4: 80 | K4: 0 | L4: 32.712149 | M4: 0.0909407 | P4: -2.42 | Q4: -4.63 | R4: 0.52
B5: 46001.474 | C5: 1 | D5: -2.1 | E5: -3.3 | F5: =E5 - (8*D5) -> 13.5 | G5: 22 | H5: 0.0031959 | I5: Stream | J5: 460 | K5: 0 | L5: 10.2811 | M5: 0.305407 | P5: -2.42 | Q5: -4.63 | R5: 0.5
B6: 46001.51 | C6: 2 | D6: -2.1 | E6: -2.7 | F6: =E6 - (8*D6) -> 14.1 | G6: 21.9 | H6: 0.01506689 | I6: Stream | J6: 270 | K6: 0 | L6: 7.0312998 | M6: 0.162014 | P6: -2.42 | Q6: -4.63 | R6: 0.47
B7: 46001.536 | C7: 3 | D7: -2.4 | E7: -4.1 | F7: =E7 - (8*D7) -> 15.1 | G7: 24 | H7: 0.07387085 | I7: Stream | J7: 230 | K7: 0 | L7: 10.034531 | M7: 0.0603415 | P7: -2.42 | Q7: -4.63 | R7: 0.53
B8: 46001.601 | C8: 6 | D8: -2.1 | E8: -3.3 | F8: =E8 - (8*D8) -> 13.5 | G8: 24.7 | H8: 0.1012935 | I8: Stream | J8: 80 | K8: 0 | L8: 8.0372761 | M8: 0.0215673 | P8: -2.42 | Q8: -4.63 | R8: 0.4
B9: 46002 | C9: 1 | D9: -1.4 | E9: 4 | F9: =E9 - (8*D9) -> 15.2 | G9: 20 | H9: =0.02832*1.76 -> 0.0498432 | I9: Rain | J9: 460 | K9: 11.684 | N9: -1.4 | O9: 4 | P9: -2.42 | Q9: -4.63
B10: 46002 | C10: 1 | D10: -1.4 | E10: 4.2 | F10: =E10 - (8*D10) -> 15.4 | G10: 20 | H10: =0.02832*1.76 -> 0.0498432 | I10: Rain | J10: 460 | K10: 11.684 | N10: -1.4 | O10: 4.2 | P10: -2.42 | Q10: -4.63
B11: 46002.396 | C11: 5 | D11: -2.3 | E11: -3.6 | F11: =E11 - (8*D11) -> 14.8 | G11: 22.1 | H11: 0.1089295 | I11: Stream | J11: 80 | K11: 0 | L11: 1.2716559 | M11: 0.0327912 | P11: -2.42 | Q11: -4.63 | R11: 0.49
B12: 46022 | C12: 1 | D12: -2.2 | E12: -4.3 | F12: =E12 - (8*D12) -> 13.3 | G12: 22 | H12: =0.02832*6.01 -> 0.1702032 | I12: Rain | J12: 460 | K12: 363.474 | N12: -2.2 | O12: -4.3 | P12: -2.42 | Q12: -4.63
B13: 46052 | C13: 1 | D13: -2.4 | E13: -3.9 | F13: =E13 - (8*D13) -> 15.3 | G13: 21 | H13: =0.02832*6.64 -> 0.1880448 | I13: Rain | J13: 460 | K13: 263.906 | N13: -2.4 | O13: -3.9 | P13: -2.42 | Q13: -4.63
B14: 46056 | C14: 1 | D14: -1.6 | E14: 0.3 | F14: =E14 - (8*D14) -> 13.1 | G14: 24 | H14: =0.02832*2.31 -> 0.0654192 | I14: Rain | J14: 460 | K14: 10.16 | N14: -1.6 | O14: 0.3 | P14: -2.42 | Q14: -4.63
B15: 46063.515 | C15: 2 | D15: -2.4 | E15: -3.5 | F15: =E15 - (8*D15) -> 15.7 | G15: 20.7 | H15: 0.44147608 | I15: Stream | J15: 270 | K15: 25.4 | L15: 2.6882586 | M15: 0.172401 | N15: -2.8 | O15: -7.5 | P15: -2.42 | Q15: -4.63 | R15: 0.61
B16: 46063.522 | C16: 3 | D16: -2.4 | E16: -3.6 | F16: =E16 - (8*D16) -> 15.6 | G16: 21 | H16: 2.1644953 | I16: Stream | J16: 230 | K16: 25.4 | L16: 4.90549 | M16: 0.0636733 | N16: -2.8 | O16: -7.5 | P16: -2.42 | Q16: -4.63 | R16: 0.66
B17: 46063.531 | C17: 4 | D17: -2.2 | E17: -2.8 | F17: =E17 - (8*D17) -> 14.8 | G17: 22.1 | H17: 2.1644953 | I17: Stream | J17: 80 | K17: 25.4 | L17: 5.3351095 | M17: 0.2293 | N17: -2.8 | O17: -7.5 | P17: -2.42 | Q17: -4.63 | R17: 0.44
B18: 46063.539 | C18: 5 | D18: -2.2 | E18: -2.7 | F18: =E18 - (8*D18) -> 14.9 | G18: 22.4 | H18: 2.836884 | I18: Stream | J18: 80 | K18: 25.4 | L18: 4.2030932 | M18: 0.0677443 | N18: -2.8 | O18: -7.5 | P18: -2.42 | Q18: -4.63 | R18: 0.66
B19: 46063.563 | C19: 6 | D19: -2.1 | E19: -2.7 | F19: =E19 - (8*D19) -> 14.1 | G19: 22.3 | H19: 3.1917515 | I19: Stream | J19: 80 | K19: 25.4 | L19: 2.0216429 | M19: 0.0233487 | N19: -2.8 | O19: -7.5 | P19: -2.42 | Q19: -4.63 | R19: 0.57
B20: 46063.582 | C20: 7 | D20: -2.1 | E20: -3 | F20: =E20 - (8*D20) -> 13.8 | G20: 22.7 | H20: 2.9680085 | I20: Stream | J20: 5 | K20: 25.4 | L20: 1.6028539 | M20: 0.0223054 | N20: -2.8 | O20: -7.5 | P20: -2.42 | Q20: -4.63 | R20: 0.6

Sheet Hailey's Data
A1: Manoa Tr- Waihi | B1: 44970.399 | C1: HP1 | D1: -2.6 | E1: -6.7 | F1: 0.03 | G1: 0.21 | H1: 18 | I1: 15.5 | J1: 173.86349 | K1: 106 | L1: 70 | M1: dD:temp | N1: =CORREL(H1:H112, E1:E112) -> 0.34868825 | O1: =I1*$O$2 -> 0.4389104 | AA1: GMWL
A2: Waaloa | B2: 44970.429 | C2: HP4 | D2: -1.9 | E2: -2.2 | F2: 0.01 | G2: 0.11 | H2: 18.8 | I2: 12.4 | J2: 177.57552 | K2: 140.6 | L2: =(63.98+70.2+57.01+47)/4 -> 59.5475 | O2: =I2*$O$2 -> 0.35112832
A3: Dole St Bridge | B3: 44972.373 | C3: HP20 | D3: -4 | E3: -21.4 | F3: 0.02 | G3: 0.11 | H3: 18.5 | I3: 15.5 | J3: 9.272717 | K3: 135.6 | O3: =I3*$O$2 -> 0.4389104 | AA3: =8.2*D3+10.8 -> -22
A4: UH Tea Garden | B4: 44972.398 | C4: HP17 | D4: -3.9 | E4: -20.6 | F4: 0.01 | G4: 0.1 | H4: 18.5 | I4: 14.5 | J4: 14.037592 | K4: 134.7 | L4: =(8.06+5.17)/2 -> 6.615 | O4: =I4*$O$2 -> 0.4105936 | AA4: =8.2*D4+10.8 -> -21.18
A5: Kaimuki High School | B5: 44974.371 | C5: HP23 | D5: -8.3 | E5: -57.5 | F5: 0.01 | G5: 0.25 | H5: 19.4 | I5: 22.1 | J5: 68.772669 | K5: 128.7 | L5: 0 | O5: =I5*$O$2 -> 0.62580128 | AA5: =8.2*D5+10.8 -> -57.26
A6: Date St Bridge | B6: 44974.385 | C6: HP26 | D6: -8.4 | E6: -58.3 | F6: 0.01 | G6: 0.16 | H6: 19.6 | I6: 19.2 | J6: 14.746977 | K6: 247.2 | L6: 0 | O6: =I6*$O$2 -> 0.54368256 | AA6: =8.2*D6+10.8 -> -58.08
A7: Ala Wai Estuary | B7: 44974.409 | C7: HP29 | D7: -6.8 | E7: -46.3 | F7: 0.03 | G7: 0.29 | H7: 20.2 | I7: 17.8 | J7: 84.999915 | K7: 6085 | L7: 0 | O7: =I7*$O$2 -> 0.50403904 | AA7: =8.2*D7+10.8 -> -44.96
A8: Pawaina Bridge | B8: 44974.433 | C8: HP7 | D8: -5 | E8: -26.9 | F8: 0.02 | G8: 0.1 | H8: 18.4 | I8: 17.1 | J8: 25.275174 | K8: 119.9 | O8: =I8*$O$2 -> 0.48421728 | AA8: =8.2*D8+10.8 -> -30.2
A9: Manoa Tr- Waihi | B9: 44977.372 | C9: HP2 | D9: -3.7 | E9: -14.1 | F9: 0.01 | G9: 0.09 | H9: 17.7 | I9: 15.1 | J9: 87.318107 | K9: 74.5 | L9: 70 | M9: dD and discharge | N9: =CORREL(I7:I119, E7:E119) -> -0.40901946 | O9: =I9*$O$2 -> 0.42758368 | AA9: =8.2*D9+10.8 -> -19.54
A10: Manoa Tr - Lua-alaea | B10: 44977.393 | C10: HP3 | D10: -2.6 | E10: -7.6 | F10: 0.01 | G10: 0.12 | H10: 18.7 | I10: =15.3 -> 15.3 | J10: 240.4219 | K10: 91.4 | O10: =I10*$O$2 -> 0.43324704 | AA10: =8.2*D10+10.8 -> -10.52
A11: Pawaina Bridge | B11: 44977.435 | C11: HP8 | D11: -3.1 | E11: -10.6 | F11: 0.03 | G11: 0.13 | H11: 19.3 | I11: 14.1 | J11: 57.954496 | K11: 126.8 | O11: =I11*$O$2 -> 0.39926688 | AA11: =8.2*D11+10.8 -> -14.62
A12: Waaloa | B12: 44977.449 | C12: HP5 | D12: -3.1 | E12: -10.3 | F12: 0.03 | G12: 0.25 | H12: 18.9 | I12: 14.8 | J12: 279.84602 | K12: 122.4 | L12: =(63.98+70.2+57.01+47)/4 -> 59.5475 | O12: =I12*$O$2 -> 0.41908864 | AA12: =8.2*D12+10.8 -> -14.62
A13: Manoa District Park | B13: 44979.367 | C13: HP11 | D13: -2.5 | E13: -6.5 | F13: 0.02 | G13: 0.05 | H13: 19.3 | I13: 20.6 | J13: 43.272689 | K13: 150.8 | L13: =(5.15+2.28+1.74+7.04)/4 -> 4.0525 | O13: =I13*$O$2 -> 0.58332608 | AA13: =8.2*D13+10.8 -> -9.7
A14: Manoa Innovation Center Bridge/Woodlawn | B14: 44979.385 | C14: HP14 | D14: -2.4 | E14: -5.7 | F14: 0.01 | G14: 0.04 | H14: 19.5 | I14: 22.4 | J14: 80.716148 | K14: 172.4 | L14: =(3.37+4.54+4.54)/3 -> 4.15 | O14: =I14*$O$2 -> 0.63429632 | AA14: =8.2*D14+10.8 -> -8.88
A15: UH Tea Garden | B15: 44979.542 | C15: HP18 | D15: -2.1 | E15: -4.2 | F15: 0.01 | G15: 0.14 | H15: 20.3 | I15: 20.9 | J15: 6.954538 | K15: 140.3 | L15: =(8.06+5.17)/2 -> 6.615 | O15: =I15*$O$2 -> 0.59182112 | AA15: =8.2*D15+10.8 -> -6.42
A16: Dole St Bridge | B16: 44979.562 | C16: HP21 | D16: -2.1 | E16: -4.1 | F16: 0.02 | G16: 0.15 | H16: 20.2 | I16: 20.9 | J16: 11.931954 | K16: 140.8 | O16: =I16*$O$2 -> 0.59182112 | AA16: =8.2*D16+10.8 -> -6.42
A17: Kaimuki High School | B17: 44981.361 | C17: HP24 | D17: -2.1 | E17: -4.4 | F17: 0.03 | G17: 0.18 | H17: 19 | I17: 12 | J17: 45.590871 | K17: 209.4 | L17: 0 | O17: =I17*$O$2 -> 0.3398016 | AA17: =8.2*D17+10.8 -> -6.42
A18: Date St Bridge | B18: 44981.375 | C18: HP27 | D18: -2.1 | E18: -4.2 | F18: 0.01 | G18: 0.23 | H18: 19.1 | I18: 11.7 | J18: 119.34456 | K18: 1058 | L18: 0 | O18: =I18*$O$2 -> 0.33130656 | AA18: =8.2*D18+10.8 -> -6.42
A19: Ala Wai Estuary | B19: 44981.396 | C19: HP30 | D19: -1.3 | E19: -1.6 | F19: 0.01 | G19: 0.1 | H19: 20.7 | I19: 13.5 | J19: 45.59087 | K19: 17408 | L19: 0 | O19: =I19*$O$2 -> 0.3822768 | AA19: =8.2*D19+10.8 -> 0.14
A20: Manoa Innovation Center Bridge/Woodlawn | B20: 44986.364 | C20: HP15 | D20: -2.8 | E20: -6.4 | F20: 0.02 | G20: 0.05 | H20: 17.7 | I20: 38.3 | J20: 3.0800034 | K20: 156 | L20: =(3.37+4.54+4.54)/3 -> 4.15 | O20: =I20*$O$2 -> 1.0845334 | AA20: =8.2*D20+10.8 -> -12.16
A21: Manoa District Park | B21: 44986.382 | C21: HP12 | D21: -2.9 | E21: -6.7 | F21: 0.01 | G21: 0.05 | H21: 17.7 | I21: 33.8 | J21: 90.586264 | K21: 128.3 | L21: =(5.15+2.28+1.74+7.04)/4 -> 4.0525 | O21: =I21*$O$2 -> 0.95710784 | AA21: =8.2*D21+10.8 -> -12.98
A22: Pawaina Bridge | B22: 44986.401 | C22: HP9 | D22: -3.1 | E22: -10.3 | F22: 0.01 | G22: 0.07 | H22: 17.5 | I22: 30.7 | J22: 6.953165 | K22: 112.2 | O22: =I22*$O$2 -> 0.86932576 | AA22: =8.2*D22+10.8 -> -14.62
A23: Pawaina Bridge | B23: 45019.382 | C23: HP10 | D23: -2.7 | E23: -6.9 | F23: 0.01 | G23: 0.05 | H23: 21.5 | I23: 22.3 | J23: 38.602018 | K23: 135 | O23: =I23*$O$2 -> 0.63146464 | AA23: =8.2*D23+10.8 -> -11.34
A24: Waaloa | B24: 45019.401 | C24: HP6 | D24: -2.7 | E24: -6.9 | F24: 0.02 | G24: 0.06 | H24: 21.2 | I24: 20.1 | J24: 46.085419 | K24: 128 | L24: =(63.98+70.2+57.01+47)/4 -> 59.5475 | O24: =I24*$O$2 -> 0.56916768 | AA24: =8.2*D24+10.8 -> -11.34
A25: Manoa District Park | B25: 45028.354 | C25: HP13 | D25: -2.3 | E25: -4.6 | F25: 0.01 | G25: 0.03 | H25: 21.6 | I25: 8.52 | J25: 21.606146 | K25: 178 | L25: =(5.15+2.28+1.74+7.04)/4 -> 4.0525 | O25: =I25*$O$2 -> 0.24125914 | AA25: =8.2*D25+10.8 -> -8.06
A26: Manoa Innovation Center Bridge/Woodlawn | B26: 45028.369 | C26: HP16 | D26: -2.3 | E26: -4.5 | F26: 0.01 | G26: 0.07 | H26: 21.8 | I26: 8.52 | J26: 85.667001 | K26: 170.4 | L26: =(3.37+4.54+4.54)/3 -> 4.15 | O26: =I26*$O$2 -> 0.24125914 | AA26: =8.2*D26+10.8 -> -8.06
A27: UH Tea Garden | B27: 45030.338 | C27: HP19 | D27: -2.1 | E27: -3.8 | F27: 0.02 | G27: 0.08 | H27: 21.4 | I27: 9.31 | J27: 4.6281233 | K27: 109.3 | L27: =(8.06+5.17)/2 -> 6.615 | O27: =I27*$O$2 -> 0.26362941 | AA27: =8.2*D27+10.8 -> -6.42
A28: Dole St Bridge | B28: 45030.351 | C28: HP22 | D28: -2.1 | E28: -3.6 | F28: 0.02 | G28: 0.03 | H28: 21.5 | I28: 9.31 | J28: 13.167262 | K28: 173.4 | O28: =I28*$O$2 -> 0.26362941 | AA28: =8.2*D28+10.8 -> -6.42
A29: Kaimuki High School | B29: 45033.361 | C29: HP25 | D29: -2.2 | E29: -4.6 | F29: 0.03 | G29: 0.06 | H29: 22.5 | I29: 4.52 | J29: 15.427078 | K29: 214.2 | L29: 0 | O29: =I29*$O$2 -> 0.12799194 | AA29: =8.2*D29+10.8 -> -7.24
A30: Date St Bridge | B30: 45033.375 | C30: HP28 | D30: -2.2 | E30: -4.7 | F30: 0.01 | G30: 0.11 | H30: 23.8 | I30: 4.52 | J30: 93.63542 | K30: 649 | L30: 0 | O30: =I30*$O$2 -> 0.12799194 | AA30: =8.2*D30+10.8 -> -7.24
A31: Ala Wai Estuary | B31: 45033.387 | C31: HP31 | D31: -1.4 | E31: -2 | F31: 0.02 | G31: 0.09 | H31: 25 | I31: 4.52 | J31: 137.16015 | K31: 18092 | L31: 0 | O31: =I31*$O$2 -> 0.12799194 | AA31: =8.2*D31+10.8 -> -0.68
A32: Manoa Tr- Waihi | B32: 45042.376 | C32: HP33 | D32: -2.6 | E32: -5.4 | F32: 0.03 | G32: 0.21 | H32: 20.4 | I32: 15.16 | J32: 89.654729 | K32: 106 | L32: 70 | M32: dD and radon | N32: =CORREL(J30:J141, E30:E141) -> 0.015535279 | O32: =I32*$O$2 -> 0.42928269 | AA32: =8.2*D32+10.8 -> -10.52
A33: Date St Bridge | B33: 45058.451 | C33: HP58 | D33: -2.4 | E33: -4.7 | F33: 0.01 | G33: 0.03 | H33: 24.6 | I33: 11.4 | J33: 34.730149 | K33: 188 | L33: 0 | O33: =I33*$O$2 -> 0.32281152 | AA33: =8.2*D33+10.8 -> -8.88
A34: Ala Wai Estuary | B34: 45058.469 | C34: HP61 | D34: -2.4 | E34: -4.4 | F34: 0.02 | G34: 0.05 | H34: 26.2 | I34: 11.1 | J34: 10.815515 | K34: 3130 | L34: 0 | O34: =I34*$O$2 -> 0.31431648 | AA34: =8.2*D34+10.8 -> -8.88
A35: Kaimuki High School | B35: 45061.424 | C35: HP55 | D35: -2.4 | E35: -4.6 | F35: 0.04 | G35: 0.19 | H35: 23.1 | I35: 6.57 | J35: 2.893458 | K35: 164 | L35: 0 | O35: =I35*$O$2 -> 0.18604138 | AA35: =8.2*D35+10.8 -> -8.88
A36: Dole St Bridge | B36: 45061.453 | C36: HP52 | D36: -2.1 | E36: -4.5 | F36: 0.02 | G36: 0.05 | H36: 21.3 | I36: 7.3 | J36: 11.570306 | K36: 174.2 | O36: =I36*$O$2 -> 0.20671264 | AA36: =8.2*D36+10.8 -> -6.42
A37: UH Tea Garden | B37: 45061.469 | C37: HP49 | D37: -2.3 | E37: -4.3 | F37: 0.02 | G37: 0.06 | H37: 21.2 | I37: 7.05 | J37: 5.7674203 | K37: 106.6 | L37: =(8.06+5.17)/2 -> 6.615 | O37: =I37*$O$2 -> 0.19963344 | AA37: =8.2*D37+10.8 -> -8.06
A38: Manoa Innovation Center Bridge/Woodlawn | B38: 45061.486 | C38: HP46 | D38: -2.4 | E38: -4.1 | F38: 0.03 | G38: 0.13 | H38: 23.6 | I38: 6.57 | J38: 90.409013 | K38: 162 | L38: =(3.37+4.54+4.54)/3 -> 4.15 | O38: =I38*$O$2 -> 0.18604138 | AA38: =8.2*D38+10.8 -> -8.88
A39: Waaloa | B39: 45062.476 | C39: HP37 | D39: -2.6 | E39: -0.2 | F39: 0.02 | G39: 0.16 | H39: 20.2 | I39: 24.8 | J39: 5.0468135 | K39: 59 | L39: =(63.98+70.2+57.01+47)/4 -> 59.5475 | O39: =I39*$O$2 -> 0.70225664 | AA39: =8.2*D39+10.8 -> -10.52
A40: Pawaina Bridge | B40: 45062.49 | C40: HP40 | D40: -2.4 | E40: -0.4 | F40: 0.02 | G40: 0.09 | H40: 20.5 | I40: 71.1 | J40: 38.592406 | K40: 76.1 | O40: =I40*$O$2 -> 2.0133245 | AA40: =8.2*D40+10.8 -> -8.88
...

Sheet Sheet1
A1: Date | B1: Time Collection | C1: Time Sampling | D1: Volume Sampled | E1: Analysis Sample Date | F1: Special Weather Event | G1: Additional Notes | H1: Weight Bucket | I1: Vial Slot | J1: Average | L1: Standard Deviation
J2: δ18O (‰) | K2: δ2H (‰) | L2: δ18O | M2: δ2H
A3: 44933.557 | H3: 586 | I3: =H3/13.27321775 -> 44.149053 | J3: -1.6 | K3: 5.1 | L3: 0.04 | M3: 0.15 | N3: =K3-(8*J3) -> 17.9
A4: 44942 | C4: 0.70833333 | E4: 20 ml | H4: 766.9 | I4: K8 | J4: 0.7 | K4: 12.4 | L4: 0.04 | M4: 0.26 | N4: =K4-8*J4 -> 6.8
A5: 44954.726 | H5: 164 | I5: =H5/13.27321775 -> 12.355708 | J5: -1.9 | K5: 3.5 | L5: 0.01 | M5: 0.06 | N5: =K5-(8*J5) -> 18.7
A6: 44955.688 | H6: 338 | I6: =H6/13.27321775 -> 25.464812 | J6: -3.5 | K6: -9.6 | L6: 0.05 | M6: 0.24 | N6: =K6-(8*J6) -> 18.4
A7: 44956 | C7: 0.70833333 | E7: 20 ml | H7: 1726.9 | I7: K9 | J7: -4.8 | K7: -20.5 | L7: 0.01 | M7: 0.07 | N7: =K7-8*J7 -> 17.9
A8: 44959.71 | H8: 394 | I8: =H8/13.27321775 -> 29.683835 | J8: -6.9 | K8: -44.4 | L8: 0.03 | M8: 0.19 | N8: =K8-(8*J8) -> 10.8
A9: 44967 | B9: 0.52083333 | D9: 10 ml | H9: 318.5 | I9: D8 | J9: -2.4 | K9: -8.4 | L9: 0.01 | M9: 0.08 | N9: =K9-8*J9 -> 10.8
A10: 44967 | E10: 10 ml | I10: A1 | J10: -2.5 | K10: -7 | L10: 0.05 | M10: 0.35 | N10: =K10-8*J10 -> 13
A11: 44972.68 | H11: 583 | I11: =H11/13.27321775 -> 43.923034 | J11: -5.1 | K11: -27.3 | L11: 0.02 | M11: 0.14 | N11: =K11-(8*J11) -> 13.5
A12: 44974 | E12: 10 ml | I12: A2 | J12: -6 | K12: -37.1 | L12: 0.01 | M12: 0.07 | N12: =K12-8*J12 -> 10.9
A13: 44975.348 | H13: 481 | I13: =H13/13.27321775 -> 36.238387 | J13: -13 | K13: -100.7 | L13: 0.02 | M13: 0.23 | N13: =K13-(8*J13) -> 3.3
A14: 44977.698 | H14: 322 | I14: =H14/13.27321775 -> 24.259377 | J14: -3.6 | K14: -14.8 | L14: 0.03 | M14: 0.07 | N14: =K14-(8*J14) -> 14
A15: 44981 | B15: 0.5625 | D15: 10 ml | H15: 990 | I15: D9 | J15: -3.8 | K15: -20.6 | L15: 0.03 | M15: 0.09 | N15: =K15-8*J15 -> 9.8
A16: 44981 | E16: 20 ml | I16: A3 | J16: -3.1 | K16: -13.6 | L16: 0.01 | M16: 0.14 | N16: =K16-8*J16 -> 11.2
A17: 44982 | C17: 0.70833333 | E17: 20 ml | H17: 2910.5 | I17: K10 | J17: -7.2 | K17: -46.9 | L17: 0.03 | M17: 0.18 | N17: =K17-8*J17 -> 10.7
A18: 44986.451 | H18: 214 | I18: =H18/13.27321775 -> 16.122692 | J18: -2.5 | K18: -6 | L18: 0.02 | M18: 0.19 | N18: =K18-(8*J18) -> 14
A19: 44988 | B19: 0.5 | D19: 20 ml | H19: 578.3 | I19: D10 | J19: -2 | K19: -3.2 | L19: 0.01 | M19: 0.07 | N19: =K19-8*J19 -> 12.8
A20: 44988 | E20: 20 ml | I20: A4 | J20: -3 | K20: -6.7 | L20: 0.02 | M20: 0.06 | N20: =K20-8*J20 -> 17.3
A21: 44990.583 | H21: 490 | I21: =H21/13.27321775 -> 36.916444 | J21: -4.4 | K21: -22.2 | L21: 0.01 | M21: 0.13 | N21: =K21-(8*J21) -> 13
A22: 44993.295 | H22: 207 | I22: =H22/13.27321775 -> 15.595314 | J22: -2.3 | K22: -5.5 | L22: 0.02 | M22: 0.17 | N22: =K22-(8*J22) -> 12.9
A23: 44995 | B23: 0.5625 | D23: 20 ml | H23: 354.4 | I23: E1 | J23: -2.4 | K23: -1.8 | L23: 0.02 | M23: 0.09 | N23: =K23-8*J23 -> 17.4
A24: 44995 | E24: 20 ml | I24: A5 | J24: -3.1 | K24: -9.9 | L24: 0.02 | M24: 0.03 | N24: =K24-8*J24 -> 14.9
A25: 45002 | B25: 0.45833333 | D25: 20 ml | H25: 243.3 | I25: E2 | J25: -1.3 | K25: -2.4 | L25: 0.02 | M25: 0.03 | N25: =K25-8*J25 -> 8
A26: 45002 | E26: 20 ml | I26: A6 | J26: -1.3 | K26: -2.3 | L26: 0.02 | M26: 0.11 | N26: =K26-8*J26 -> 8.1
A27: 45007 | E27: 20 ml | I27: A7 | J27: -1.4 | K27: 1.4 | L27: 0.01 | M27: 0.09 | N27: =K27-8*J27 -> 12.6
A28: 45007.519 | H28: 266 | I28: =H28/13.27321775 -> 20.040355 | J28: -1.4 | K28: -3.1 | L28: 0.02 | M28: 0.02 | N28: =K28-(8*J28) -> 8.1
A29: 45011 | C29: 0.70833333 | E29: 20 ml | H29: 2103.2 | I29: L1 | J29: -2.4 | K29: -6.8 | L29: 0.05 | M29: 0.21 | N29: =K29-8*J29 -> 12.4
A30: 45014 | C30: 0.51597222 | E30: 20 ml | H30: 549.4 g | I30: A8 | J30: -1.2 | K30: 2.5 | L30: 0.02 | M30: 0.05 | N30: =K30-8*J30 -> 12.1
A31: 45014.706 | H31: 293 | I31: =H31/13.27321775 -> 22.074527 | J31: -1.1 | K31: 2.3 | L31: 0.01 | M31: 0.06 | N31: =K31-(8*J31) -> 11.1
A32: 45016 | B32: 0.64583333 | D32: 20 ml | H32: 289.1 | I32: E3 | J32: -1.2 | K32: 0.5 | L32: 0.03 | M32: 0.04 | N32: =K32-8*J32 -> 10.1
A33: 45021 | B33: 0.47916667 | C33: 0.5 | D33: 20 ml | F33: Thunderstorm and a lot of rain on (4/3/2023) | H33: 863.1 g | I33: E4 | J33: -3.7 | K33: -15 | L33: 0.03 | M33: 0.1 | N33: =K33-8*J33 -> 14.6
A34: 45025.366 | H34: 276 | I34: =H34/13.27321775 -> 20.793752 | J34: -2.4 | K34: -6.7 | L34: 0.02 | M34: 0.13 | N34: =K34-(8*J34) -> 12.5
A35: 45028 | B35: 0.48958333 | C35: 0.49652778 | D35: 20 ml | H35: 310.5 g | I35: E5 | J35: -0.7 | K35: 4.6 | L35: 0.03 | M35: 0.37 | N35: =K35-8*J35 -> 10.2
A36: 45028 | C36: 0.55763889 | D36: 0.59027778 | E36: 20 ml | G36: Bucket was so full that their might be water in the tube | H36: 3652.4 g | I36: A9 | J36: -2.6 | K36: -6.1 | L36: 0.02 | M36: 0.1 | N36: =K36-8*J36 -> 14.7
A37: 45032 | C37: 0.70833333 | E37: 20 ml | H37: 1364.3 | I37: L2 | J37: -1 | K37: 2.4 | L37: 0.02 | M37: 0.13 | N37: =K37-8*J37 -> 10.4
A38: 45032.688 | H38: 74 | I38: =H38/13.27321775 -> 5.5751364 | J38: -1.5 | K38: 1.4 | L38: 0.02 | M38: 0.05 | N38: =K38-(8*J38) -> 13.4
A39: 45035 | B39: 0.48611111 | C39: 0.49652778 | D39: 20 ml | F39: Heavy rain the overnight | H39: 698.4 g | I39: E6 | J39: -3.1 | K39: -14.6 | L39: 0.02 | M39: 0.05 | N39: =K39-8*J39 -> 10.2
A40: 45035.306 | H40: 684 | I40: =H40/13.27321775 -> 51.532342 | J40: -2.4 | K40: -12.2 | L40: 0.02 | M40: 0.14 | N40: =K40-(8*J40) -> 7
...

Sheet Sheet2
B2: Date Collected | C2: Average
C3: δ18O (‰) | D3: δ2H (‰)
B4: 44967 | C4: -2.5 | D4: -7
B5: 44974 | C5: -6 | D5: -37.1
B6: 44981 | C6: -3.1 | D6: -13.6
B7: 44988 | C7: -3 | D7: -6.7
B8: 44995 | C8: -3.1 | D8: -9.9
B9: 45002 | C9: -1.3 | D9: -2.3
B10: 45007 | C10: -1.4 | D10: 1.4
B11: 45014 | C11: -1.2 | D11: 2.5
B12: 45028 | C12: -2.6 | D12: -6.1
B13: 45036 | C13: -0.8 | D13: -1.7
B14: 45044 | C14: -1.3 | D14: 1.5
B15: 45049 | C15: -1.9 | D15: 0.3
... B40: 45267 | C40: -4.6 | D40: -25.2
